Workbook
Name Slicer_Month_Name: #N/A
Name Slicer_Month_Name1: #N/A
Name Slicer_Property_Type: #N/A
Name Slicer_Town: #N/A
Name Slicer_Town_initials_PQ: #N/A
Name Slicer_Year: #N/A

Sheet Table1_3__3
A1: Serial Number | B1: Date Recorded | C1: Town | D1: Address | E1: Assessed Value | F1: Sale Amount | G1: Sales Ratio | H1: Sales Ratio 2 | I1: Property Type | J1: Value Status
A2: 160092 | B2: 42724 | C2: Rocky Hill | D2: 13D ROBBINS LANE | E2: 45150 | F2: 13650000 | G2: 0.003307692 | H2: 302.32558 | I2: Condo | J2: Overvalued
A3: 200195 | B3: 44312 | C3: Cromwell | D3: 34 SHUNPIKE ROAD | E3: 3360000 | F3: 5214750 | G3: 0.6443 | H3: 1.5520089 | I3: Commercial | J3: Undervalued
A4: 201233 | B4: 44369 | C4: Greenwich | D4: 11 BAYBERRY LANE | E4: 4259500 | F4: 4300000 | G4: 0.9905 | H4: 1.0095082 | I4: Residential | J4: Undervalued
A5: 170261 | B5: 43221 | C5: New London | D5: 83 MANSFIELD RD 228 | E5: 30660 | F5: 3266250 | G5: 0.009386912 | H5: 106.53131 | I5: Condo | J5: Overvalued
A6: 170255 | B6: 43221 | C6: New London | D6: 83 MANSFIELD RD 220 | E6: 30660 | F6: 3266250 | G6: 0.009386912 | H6: 106.53131 | I6: Condo | J6: Overvalued
A7: 201186 | B7: 44389 | C7: Danbury | D7: 28 MAIN ST | E7: 695500 | F7: 3200000 | G7: 0.21734375 | H7: 4.6010065 | I7: Commercial | J7: Overvalued
A8: 200645 | B8: 44244 | C8: Greenwich | D8: 123 VALLEY DRIVE | E8: 2661200 | F8: 3000000 | G8: 0.887 | H8: 1.127311 | I8: Residential | J8: Undervalued
A9: 200661 | B9: 44438 | C9: New Canaan | D9: 322 MAIN ST | E9: 1279460 | F9: 2400000 | G9: 0.5331 | H9: 1.8757913 | I9: Residential | J9: Undervalued
A10: 201437 | B10: 44397 | C10: Greenwich | D10: 552 RIVER ROAD | E10: 1337630 | F10: 2300000 | G10: 0.5815 | H10: 1.719459 | I10: Residential | J10: Undervalued
A11: 200055 | B11: 44221 | C11: Washington | D11: 136 OLD LITCHFIELD RD | E11: 1030330 | F11: 2285000 | G11: 0.4509 | H11: 2.2177361 | I11: Residential | J11: Overvalued
A12: 2016743 | B12: 44396 | C12: Redding | D12: 241 ETHAN ALLEN HIGHWAY | E12: 1769800 | F12: 1800000 | G12: 0.9832 | H12: 1.0170641 | I12: Commercial | J12: Undervalued
A13: 200320 | B13: 44326 | C13: East Lyme | D13: 9 FREEDOM WAY | E13: 776230 | F13: 1525000 | G13: 0.509 | H13: 1.9646239 | I13: Commercial | J13: Undervalued
... A142: 20200070 | B142: 44294 | C142: Sharon | D142: 101 MILLERTON RD | E142: 170200 | F142: 287000 | G142: 0.593 | H142: 1.6862515 | I142: Residential | J142: Undervalued
A143: 100089 | B143: 40569 | C143: Berlin | D143: 63 BANNAN LN | E143: 0 | F143: 283491 | G143: 0 | I143: Condo | J143: Overvalued
A144: 200709 | B144: 44302 | C144: Manchester | D144: 152 GREEN ROAD | E144: 138100 | F144: 282500 | G144: 0.48884956 | H144: 2.0456191 | I144: Residential | J144: Overvalued
A145: 200117 | B145: 44298 | C145: Canton | D145: 52 COUNTRY LANE | E145: 160850 | F145: 280000 | G145: 0.5744 | H145: 1.7407523 | I145: Residential | J145: Undervalued
A146: 90472 | B146: 40331 | C146: Fairfield | D146: 245 SUNNYRIDGE AVENUE UNIT#16 | E146: 220920 | F146: 280000 | G146: 0.789 | H146: 1.2674271 | I146: Condo | J146: Undervalued
A147: 20899 | B147: 44368 | C147: Hartford | D147: 159 RUSS ST | E147: 137270 | F147: 278500 | G147: 0.4928 | H147: 2.0288483 | I147: Apartments | J147: Overvalued
A148: 160197 | B148: 42675 | C148: Stamford | D148: 300 BROAD STREET # 502 | E148: 143650 | F148: 278000 | G148: 0.51672662 | H148: 1.9352593 | I148: Condo | J148: Undervalued
A149: 2000327 | B149: 44258 | C149: Naugatuck | D149: 31 PILGRIM LN | E149: 157810 | F149: 276500 | G149: 0.5707 | H149: 1.752107 | I149: Residential | J149: Undervalued
A150: 20200059 | B150: 44117 | C150: Stratford | D150: 653B OSAGE LANE | E150: 156380 | F150: 276000 | G150: 0.5665 | H150: 1.7649316 | I150: Residential | J150: Undervalued
A151: 90042 | B151: 40106 | C151: Hamden | D151: 1151 WHITNEY AVE UB4 | E151: 219870 | F151: 275000 | G151: 0.79952727 | H151: 1.2507391 | I151: Condo | J151: Undervalued
A152: 90113 | B152: 40150 | C152: Vernon | D152: 13 LANTERN LN | E152: 176220 | F152: 270000 | G152: 0.65266667 | H152: 1.5321757 | I152: Condo | J152: Undervalued
A153: 200025 | B153: 44124 | C153: Suffield | D153: 930 BRANCH RD | E153: 159180 | F153: 261000 | G153: 0.6098 | H153: 1.6396532 | I153: Residential | J153: Undervalued
A154: 200408 | B154: 44189 | C154: Danbury | D154: 15 SCUPPO RD 1503 | E154: 130800 | F154: 260000 | G154: 0.503 | H154: 1.9877676 | I154: Residential | J154: Undervalued
A155: 201245 | B155: 44453 | C155: Meriden | D155: 223 REYNOLDS DR | E155: 128170 | F155: 260000 | G155: 0.4929 | H155: 2.0285558 | I155: Residential | J155: Overvalued
... A315: 2000720 | B315: 44201 | C315: Stamford | D315: 57 HARBOR DRIVE GARAGE G-105B | E315: 19110 | F315: 27500 | G315: 0.6949 | H315: 1.4390372 | I315: Residential | J315: Undervalued

Sheet overvalued_sales ratio2 by town
A1: Town | B1: Overvalued Count
A2: Hartford | B2: 7
A3: Stamford | B3: 5
A4: Waterbury | B4: 4
A5: New Haven | B5: 4
A6: Danbury | B6: 3
A7: Norwalk | B7: 2
A8: New London | B8: 2
A9: Plainfield | B9: 2
A10: Meriden | B10: 2
A11: Groton | B11: 2
A12: Southbury | B12: 2
A13: Vernon | B13: 1
... A43: Bridgeport | B43: 1

Sheet Table1_3__3 (2)
A1: Serial Number | B1: Date Recorded | C1: Month Name | D1: Year | E1: Month/Year | F1: Town | G1: Town Initials | H1: Address | I1: Assessed Value | J1: Sale Amount | K1: Sales Ratio | L1: Sales Ratio 2 | M1: Property Type | N1: Value Status | O1: Column1
A2: 160092 | B2: 42724 | C2: December | D2: 2016 | E2: 42705 | F2: Rocky Hill | G2: R | H2: 13D ROBBINS LANE | I2: 45150 | J2: 13650000 | K2: 0.003307692 | L2: 302.32558 | M2: Condo | N2: Overvalued
A3: 200195 | B3: 44312 | C3: April | D3: 2021 | E3: 44287 | F3: Cromwell | G3: C | H3: 34 SHUNPIKE ROAD | I3: 3360000 | J3: 5214750 | K3: 0.6443 | L3: 1.5520089 | M3: Commercial | N3: Undervalued
A4: 201233 | B4: 44369 | C4: June | D4: 2021 | E4: 44348 | F4: Greenwich | G4: G | H4: 11 BAYBERRY LANE | I4: 4259500 | J4: 4300000 | K4: 0.9905 | L4: 1.0095082 | M4: Residential | N4: Undervalued | R4: =COUNTIF(Table1_3__3[Sales Ratio 2],"<1") -> 0
A5: 170261 | B5: 43221 | C5: May | D5: 2018 | E5: 43221 | F5: New London | G5: N | H5: 83 MANSFIELD RD 228 | I5: 30660 | J5: 3266250 | K5: 0.009386912 | L5: 106.53131 | M5: Condo | N5: Overvalued
A6: 170255 | B6: 43221 | C6: May | D6: 2018 | E6: 43221 | F6: New London | G6: N | H6: 83 MANSFIELD RD 220 | I6: 30660 | J6: 3266250 | K6: 0.009386912 | L6: 106.53131 | M6: Condo | N6: Overvalued
A7: 201186 | B7: 44389 | C7: July | D7: 2021 | E7: 44378 | F7: Danbury | G7: D | H7: 28 MAIN ST | I7: 695500 | J7: 3200000 | K7: 0.21734375 | L7: 4.6010065 | M7: Commercial | N7: Overvalued
A8: 200645 | B8: 44244 | C8: February | D8: 2021 | E8: 44228 | F8: Greenwich | G8: G | H8: 123 VALLEY DRIVE | I8: 2661200 | J8: 3000000 | K8: 0.887 | L8: 1.127311 | M8: Residential | N8: Undervalued
A9: 200661 | B9: 44438 | C9: August | D9: 2021 | E9: 44409 | F9: New Canaan | G9: N | H9: 322 MAIN ST | I9: 1279460 | J9: 2400000 | K9: 0.5331 | L9: 1.8757913 | M9: Residential | N9: Undervalued
A10: 201437 | B10: 44397 | C10: July | D10: 2021 | E10: 44378 | F10: Greenwich | G10: G | H10: 552 RIVER ROAD | I10: 1337630 | J10: 2300000 | K10: 0.5815 | L10: 1.719459 | M10: Residential | N10: Undervalued
A11: 200055 | B11: 44221 | C11: January | D11: 2021 | E11: 44197 | F11: Washington | G11: W | H11: 136 OLD LITCHFIELD RD | I11: 1030330 | J11: 2285000 | K11: 0.4509 | L11: 2.2177361 | M11: Residential | N11: Overvalued
A12: 2016743 | B12: 44396 | C12: July | D12: 2021 | E12: 44378 | F12: Redding | G12: R | H12: 241 ETHAN ALLEN HIGHWAY | I12: 1769800 | J12: 1800000 | K12: 0.9832 | L12: 1.0170641 | M12: Commercial | N12: Undervalued
A13: 200320 | B13: 44326 | C13: May | D13: 2021 | E13: 44317 | F13: East Lyme | G13: E | H13: 9 FREEDOM WAY | I13: 776230 | J13: 1525000 | K13: 0.509 | L13: 1.9646239 | M13: Commercial | N13: Undervalued
A14: 200377 | B14: 44379 | C14: July | D14: 2021 | E14: 44378 | F14: Avon | G14: A | H14: 70 FAR HILLS DRIVE | I14: 862330 | J14: 1447500 | K14: 0.5957 | L14: 1.6785917 | M14: Residential | N14: Undervalued
A15: 161304 | B15: 42901 | C15: June | D15: 2017 | E15: 42887 | F15: Stamford | G15: S | H15: 12 DRYDEN STREET 1B | I15: 91980 | J15: 1323338 | K15: 0.069506052 | L15: 14.387236 | M15: Condo | N15: Overvalued
A16: 201494 | B16: 44405 | C16: July | D16: 2021 | E16: 44378 | F16: Greenwich | G16: G | H16: 20 EAST LYON FARM DRIVE | I16: 632170 | J16: 1250000 | K16: 0.5057 | L16: 1.9773162 | M16: Residential | N16: Undervalued
... A303: 2000720 | B303: 44201 | C303: January | D303: 2021 | E303: 44197 | F303: Stamford | G303: S | H303: 57 HARBOR DRIVE GARAGE G-105B | I303: 19110 | J303: 27500 | K303: 0.6949 | L303: 1.4390372 | M303: Residential | N303: Undervalued

Sheet avg. sales ratio fr comm
A1: Table1_3__3__3
A2: 1.7091373

Sheet Avg. comm vs Residential sales
A1: Serial Number | B1: Date Recorded | C1: Month Name | D1: Year | E1: Month/Year | F1: Town | G1: Town Initials | H1: Address | I1: Assessed Value | J1: Sale Amount | K1: Sales Ratio | L1: Sales Ratio 2 | M1: Property Type | N1: Value Status | O1: Column1
A2: 200195 | B2: 44312 | C2: April | D2: 2021 | E2: 44287 | F2: Cromwell | G2: C | H2: 34 SHUNPIKE ROAD | I2: 3360000 | J2: 5214750 | K2: 0.6443 | L2: 1.5520089 | M2: Commercial | N2: Undervalued
A3: 201233 | B3: 44369 | C3: June | D3: 2021 | E3: 44348 | F3: Greenwich | G3: G | H3: 11 BAYBERRY LANE | I3: 4259500 | J3: 4300000 | K3: 0.9905 | L3: 1.0095082 | M3: Residential | N3: Undervalued
A4: 201186 | B4: 44389 | C4: July | D4: 2021 | E4: 44378 | F4: Danbury | G4: D | H4: 28 MAIN ST | I4: 695500 | J4: 3200000 | K4: 0.21734375 | L4: 4.6010065 | M4: Commercial | N4: Overvalued
A5: 200645 | B5: 44244 | C5: February | D5: 2021 | E5: 44228 | F5: Greenwich | G5: G | H5: 123 VALLEY DRIVE | I5: 2661200 | J5: 3000000 | K5: 0.887 | L5: 1.127311 | M5: Residential | N5: Undervalued
A6: 200661 | B6: 44438 | C6: August | D6: 2021 | E6: 44409 | F6: New Canaan | G6: N | H6: 322 MAIN ST | I6: 1279460 | J6: 2400000 | K6: 0.5331 | L6: 1.8757913 | M6: Residential | N6: Undervalued
A7: 201437 | B7: 44397 | C7: July | D7: 2021 | E7: 44378 | F7: Greenwich | G7: G | H7: 552 RIVER ROAD | I7: 1337630 | J7: 2300000 | K7: 0.5815 | L7: 1.719459 | M7: Residential | N7: Undervalued
A8: 200055 | B8: 44221 | C8: January | D8: 2021 | E8: 44197 | F8: Washington | G8: W | H8: 136 OLD LITCHFIELD RD | I8: 1030330 | J8: 2285000 | K8: 0.4509 | L8: 2.2177361 | M8: Residential | N8: Overvalued
A9: 2016743 | B9: 44396 | C9: July | D9: 2021 | E9: 44378 | F9: Redding | G9: R | H9: 241 ETHAN ALLEN HIGHWAY | I9: 1769800 | J9: 1800000 | K9: 0.9832 | L9: 1.0170641 | M9: Commercial | N9: Undervalued
A10: 200320 | B10: 44326 | C10: May | D10: 2021 | E10: 44317 | F10: East Lyme | G10: E | H10: 9 FREEDOM WAY | I10: 776230 | J10: 1525000 | K10: 0.509 | L10: 1.9646239 | M10: Commercial | N10: Undervalued
A11: 200377 | B11: 44379 | C11: July | D11: 2021 | E11: 44378 | F11: Avon | G11: A | H11: 70 FAR HILLS DRIVE | I11: 862330 | J11: 1447500 | K11: 0.5957 | L11: 1.6785917 | M11: Residential | N11: Undervalued
A12: 201494 | B12: 44405 | C12: July | D12: 2021 | E12: 44378 | F12: Greenwich | G12: G | H12: 20 EAST LYON FARM DRIVE | I12: 632170 | J12: 1250000 | K12: 0.5057 | L12: 1.9773162 | M12: Residential | N12: Undervalued
A13: 200109 | B13: 44174 | C13: December | D13: 2020 | E13: 44166 | F13: Avon | G13: A | H13: 57 FAR HILLS DRIVE | I13: 847520 | J13: 1250000 | K13: 0.678 | L13: 1.4748914 | M13: Residential | N13: Undervalued
... A190: 2000720 | B190: 44201 | C190: January | D190: 2021 | E190: 44197 | F190: Stamford | G190: S | H190: 57 HARBOR DRIVE GARAGE G-105B | I190: 19110 | J190: 27500 | K190: 0.6949 | L190: 1.4390372 | M190: Residential | N190: Undervalued

Sheet Monthly Trend
A1: Month Name | B1: Monthly Trend
A2: December | B2: 21019750
A3: July | B3: 19705766
A4: May | B4: 16335860
A5: June | B5: 13613338
A6: September | B6: 12590314
A7: April | B7: 10525618
A8: March | B8: 9929200
A9: August | B9: 8461250
A10: October | B10: 8302200
A11: January | B11: 7682911
A12: February | B12: 6840800
A13: November | B13: 5424626

Sheet 2018-2021 Monthly Trend
A1: Month Name | B1: Sales
A2: July | B2: 18232500
A3: May | B3: 13799650
A4: April | B4: 9926618
A5: June | B5: 9165300
A6: September | B6: 9003365
A7: March | B7: 8580700
A8: August | B8: 7569800
A9: January | B9: 7332711
A10: October | B10: 6832000
A11: February | B11: 6027800
A12: December | B12: 5553900
A13: November | B13: 3652005

Sheet 2018-2021
A1: Serial Number | B1: Date Recorded | C1: Month Name | D1: Year | E1: Month/Year | F1: Town | G1: Town Initials | H1: Address | I1: Assessed Value | J1: Sale Amount | K1: Sales Ratio | L1: Sales Ratio 2 | M1: Property Type | N1: Value Status | O1: Column1 | P1: Column12 | Q1: Column2 | R1: Column3
A2: 200195 | B2: 4/26/2021 | C2: April | D2: 2021 | E2: 44287 | F2: Cromwell | G2: C | H2: 34 SHUNPIKE ROAD | I2: 3360000 | J2: 5214750 | K2: 0.6443 | L2: 1.5520089 | M2: Commercial | N2: Undervalued | P2: =TEXT(Table1_3__3__7[[#This Row],[Date Recorded]], "mmm") -> Apr | Q2: 2021 | R2: {=MONTH(Table1_3__3__7[Date Recorded])} -> 4
A3: 201233 | B3: 6/22/2021 | C3: June | D3: 2021 | E3: 44348 | F3: Greenwich | G3: G | H3: 11 BAYBERRY LANE | I3: 4259500 | J3: 4300000 | K3: 0.9905 | L3: 1.0095082 | M3: Residential | N3: Undervalued | P3: =TEXT(Table1_3__3__7[[#This Row],[Date Recorded]], "mmm") -> Jun | Q3: 2021 | R3: {=MONTH(Table1_3__3__7[Date Recorded])} -> 4
A4: 170261 | B4: 5/1/2018 | C4: May | D4: 2018 | E4: 43221 | F4: New London | G4: N | H4: 83 MANSFIELD RD 228 | I4: 30660 | J4: 3266250 | K4: 0.009386912 | L4: 106.53131 | M4: Condo | N4: Overvalued | P4: =TEXT(Table1_3__3__7[[#This Row],[Date Recorded]], "mmm") -> May | Q4: 2018 | R4: {=MONTH(Table1_3__3__7[Date Recorded])} -> 4
A5: 170255 | B5: 5/1/2018 | C5: May | D5: 2018 | E5: 43221 | F5: New London | G5: N | H5: 83 MANSFIELD RD 220 | I5: 30660 | J5: 3266250 | K5: 0.009386912 | L5: 106.53131 | M5: Condo | N5: Overvalued | P5: =TEXT(Table1_3__3__7[[#This Row],[Date Recorded]], "mmm") -> May | Q5: 2018 | R5: {=MONTH(Table1_3__3__7[Date Recorded])} -> 4
A6: 201186 | B6: 7/12/2021 | C6: July | D6: 2021 | E6: 44378 | F6: Danbury | G6: D | H6: 28 MAIN ST | I6: 695500 | J6: 3200000 | K6: 0.21734375 | L6: 4.6010065 | M6: Commercial | N6: Overvalued | P6: =TEXT(Table1_3__3__7[[#This Row],[Date Recorded]], "mmm") -> Jul | Q6: 2021 | R6: {=MONTH(Table1_3__3__7[Date Recorded])} -> 4
A7: 200645 | B7: 2/17/2021 | C7: February | D7: 2021 | E7: 44228 | F7: Greenwich | G7: G | H7: 123 VALLEY DRIVE | I7: 2661200 | J7: 3000000 | K7: 0.887 | L7: 1.127311 | M7: Residential | N7: Undervalued | P7: =TEXT(Table1_3__3__7[[#This Row],[Date Recorded]], "mmm") -> Feb | Q7: 2021 | R7: {=MONTH(Table1_3__3__7[Date Recorded])} -> 4
A8: 200661 | B8: 8/30/2021 | C8: August | D8: 2021 | E8: 44409 | F8: New Canaan | G8: N | H8: 322 MAIN ST | I8: 1279460 | J8: 2400000 | K8: 0.5331 | L8: 1.8757913 | M8: Residential | N8: Undervalued | P8: =TEXT(Table1_3__3__7[[#This Row],[Date Recorded]], "mmm") -> Aug | Q8: 2021 | R8: {=MONTH(Table1_3__3__7[Date Recorded])} -> 4
A9: 201437 | B9: 7/20/2021 | C9: July | D9: 2021 | E9: 44378 | F9: Greenwich | G9: G | H9: 552 RIVER ROAD | I9: 1337630 | J9: 2300000 | K9: 0.5815 | L9: 1.719459 | M9: Residential | N9: Undervalued | P9: =TEXT(Table1_3__3__7[[#This Row],[Date Recorded]], "mmm") -> Jul | Q9: 2021 | R9: {=MONTH(Table1_3__3__7[Date Recorded])} -> 4
A10: 200055 | B10: 1/25/2021 | C10: January | D10: 2021 | E10: 44197 | F10: Washington | G10: W | H10: 136 OLD LITCHFIELD RD | I10: 1030330 | J10: 2285000 | K10: 0.4509 | L10: 2.2177361 | M10: Residential | N10: Overvalued | P10: =TEXT(Table1_3__3__7[[#This Row],[Date Recorded]], "mmm") -> Jan | Q10: 2021 | R10: {=MONTH(Table1_3__3__7[Date Recorded])} -> 4
A11: 2016743 | B11: 7/19/2021 | C11: July | D11: 2021 | E11: 44378 | F11: Redding | G11: R | H11: 241 ETHAN ALLEN HIGHWAY | I11: 1769800 | J11: 1800000 | K11: 0.9832 | L11: 1.0170641 | M11: Commercial | N11: Undervalued | P11: =TEXT(Table1_3__3__7[[#This Row],[Date Recorded]], "mmm") -> Jul | Q11: 2021 | R11: {=MONTH(Table1_3__3__7[Date Recorded])} -> 4
A12: 200320 | B12: 5/10/2021 | C12: May | D12: 2021 | E12: 44317 | F12: East Lyme | G12: E | H12: 9 FREEDOM WAY | I12: 776230 | J12: 1525000 | K12: 0.509 | L12: 1.9646239 | M12: Commercial | N12: Undervalued | P12: =TEXT(Table1_3__3__7[[#This Row],[Date Recorded]], "mmm") -> May | Q12: 2021 | R12: {=MONTH(Table1_3__3__7[Date Recorded])} -> 4
A13: 200377 | B13: 7/2/2021 | C13: July | D13: 2021 | E13: 44378 | F13: Avon | G13: A | H13: 70 FAR HILLS DRIVE | I13: 862330 | J13: 1447500 | K13: 0.5957 | L13: 1.6785917 | M13: Residential | N13: Undervalued | P13: =TEXT(Table1_3__3__7[[#This Row],[Date Recorded]], "mmm") -> Jul | Q13: 2021 | R13: {=MONTH(Table1_3__3__7[Date Recorded])} -> 4
... A205: 180558 | B205: 5/21/2019 | C205: May | D205: 2019 | E205: 43586 | F205: New Haven | G205: N | H205: 1203 ELLA T GRASSO BLVD # B | I205: 28910 | J205: 30000 | K205: 0.9636 | L205: 1.0377032 | M205: Condo | N205: Undervalued | P205: =TEXT(Table1_3__3__7[[#This Row],[Date Recorded]], "mmm") -> May | Q205: 2019 | R205: {=MONTH(Table1_3__3__7[Date Recorded])} -> 4
A206: 2000720 | B206: 1/5/2021 | C206: January | D206: 2021 | E206: 44197 | F206: Stamford | G206: S | H206: 57 HARBOR DRIVE GARAGE G-105B | I206: 19110 | J206: 27500 | K206: 0.6949 | L206: 1.4390372 | M206: Residential | N206: Undervalued | R206: {=MONTH(Table1_3__3__7[Date Recorded])} -> 4
A207: Total | P207: =SUBTOTAL(103,Table1_3__3__7[Column12]) -> 204

Sheet Table1_3__3__9 (2)
A1: Serial Number | B1: Date Recorded | C1: Month Name | D1: Year | E1: Month/Year | F1: Town | G1: Address | H1: Assessed Value | I1: Sale Amount | J1: Sales Ratio | K1: Sales Ratio 2 | L1: Property Type | M1: Value Status | N1: Town Initials
A2: 160092 | B2: 42724 | C2: December | D2: 2016 | E2: 42705 | F2: Rocky Hill | G2: 13D ROBBINS LANE | H2: 45150 | I2: 13650000 | J2: 0.003307692 | K2: 302.32558 | L2: Condo | M2: Overvalued | N2: R
A3: 200195 | B3: 44312 | C3: April | D3: 2021 | E3: 44287 | F3: Cromwell | G3: 34 SHUNPIKE ROAD | H3: 3360000 | I3: 5214750 | J3: 0.6443 | K3: 1.5520089 | L3: Commercial | M3: Undervalued | N3: C
A4: 201233 | B4: 44369 | C4: June | D4: 2021 | E4: 44348 | F4: Greenwich | G4: 11 BAYBERRY LANE | H4: 4259500 | I4: 4300000 | J4: 0.9905 | K4: 1.0095082 | L4: Residential | M4: Undervalued | N4: G
A5: 170261 | B5: 43221 | C5: May | D5: 2018 | E5: 43221 | F5: New London | G5: 83 MANSFIELD RD 228 | H5: 30660 | I5: 3266250 | J5: 0.009386912 | K5: 106.53131 | L5: Condo | M5: Overvalued | N5: N
A6: 170255 | B6: 43221 | C6: May | D6: 2018 | E6: 43221 | F6: New London | G6: 83 MANSFIELD RD 220 | H6: 30660 | I6: 3266250 | J6: 0.009386912 | K6: 106.53131 | L6: Condo | M6: Overvalued | N6: N
A7: 201186 | B7: 44389 | C7: July | D7: 2021 | E7: 44378 | F7: Danbury | G7: 28 MAIN ST | H7: 695500 | I7: 3200000 | J7: 0.21734375 | K7: 4.6010065 | L7: Commercial | M7: Overvalued | N7: D
A8: 200645 | B8: 44244 | C8: February | D8: 2021 | E8: 44228 | F8: Greenwich | G8: 123 VALLEY DRIVE | H8: 2661200 | I8: 3000000 | J8: 0.887 | K8: 1.127311 | L8: Residential | M8: Undervalued | N8: G
A9: 200661 | B9: 44438 | C9: August | D9: 2021 | E9: 44409 | F9: New Canaan | G9: 322 MAIN ST | H9: 1279460 | I9: 2400000 | J9: 0.5331 | K9: 1.8757913 | L9: Residential | M9: Undervalued | N9: N
A10: 201437 | B10: 44397 | C10: July | D10: 2021 | E10: 44378 | F10: Greenwich | G10: 552 RIVER ROAD | H10: 1337630 | I10: 2300000 | J10: 0.5815 | K10: 1.719459 | L10: Residential | M10: Undervalued | N10: G
A11: 200055 | B11: 44221 | C11: January | D11: 2021 | E11: 44197 | F11: Washington | G11: 136 OLD LITCHFIELD RD | H11: 1030330 | I11: 2285000 | J11: 0.4509 | K11: 2.2177361 | L11: Residential | M11: Overvalued | N11: W
A12: 2016743 | B12: 44396 | C12: July | D12: 2021 | E12: 44378 | F12: Redding | G12: 241 ETHAN ALLEN HIGHWAY | H12: 1769800 | I12: 1800000 | J12: 0.9832 | K12: 1.0170641 | L12: Commercial | M12: Undervalued | N12: R
A13: 200320 | B13: 44326 | C13: May | D13: 2021 | E13: 44317 | F13: East Lyme | G13: 9 FREEDOM WAY | H13: 776230 | I13: 1525000 | J13: 0.509 | K13: 1.9646239 | L13: Commercial | M13: Undervalued | N13: E
... A303: 2000720 | B303: 44201 | C303: January | D303: 2021 | E303: 44197 | F303: Stamford | G303: 57 HARBOR DRIVE GARAGE G-105B | H303: 19110 | I303: 27500 | J303: 0.6949 | K303: 1.4390372 | L303: Residential | M303: Undervalued | N303: S

Sheet Main dataset
A1: Serial Number | B1: Date Recorded | C1: Month Name | D1: Year | E1: Month/Year | F1: Town | G1: Column2 | H1: Address | I1: Assessed Value | J1: Sale Amount | K1: Sales Ratio | L1: Sales Ratio 2 | M1: Property Type | N1: Value Status | O1: Column1
A2: 160092 | B2: 42724 | C2: December | D2: 2016 | E2: December,2016 | F2: Rocky Hill | G2: R | H2: 13D ROBBINS LANE | I2: 45150 | J2: 13650000 | K2: 0.003307692 | L2: 302.32558 | M2: Condo | N2: Overvalued
A3: 200195 | B3: 44312 | C3: April | D3: 2021 | E3: April,2021 | F3: Cromwell | G3: C | H3: 34 SHUNPIKE ROAD | I3: 3360000 | J3: 5214750 | K3: 0.6443 | L3: 1.5520089 | M3: Commercial | N3: Undervalued
A4: 201233 | B4: 44369 | C4: June | D4: 2021 | E4: June,2021 | F4: Greenwich | G4: G | H4: 11 BAYBERRY LANE | I4: 4259500 | J4: 4300000 | K4: 0.9905 | L4: 1.0095082 | M4: Residential | N4: Undervalued
A5: 170261 | B5: 43221 | C5: May | D5: 2018 | E5: May,2018 | F5: New London | G5: N | H5: 83 MANSFIELD RD 228 | I5: 30660 | J5: 3266250 | K5: 0.009386912 | L5: 106.53131 | M5: Condo | N5: Overvalued
A6: 170255 | B6: 43221 | C6: May | D6: 2018 | E6: May,2018 | F6: New London | G6: N | H6: 83 MANSFIELD RD 220 | I6: 30660 | J6: 3266250 | K6: 0.009386912 | L6: 106.53131 | M6: Condo | N6: Overvalued
A7: 201186 | B7: 44389 | C7: July | D7: 2021 | E7: July,2021 | F7: Danbury | G7: D | H7: 28 MAIN ST | I7: 695500 | J7: 3200000 | K7: 0.21734375 | L7: 4.6010065 | M7: Commercial | N7: Overvalued
A8: 200645 | B8: 44244 | C8: February | D8: 2021 | E8: February,2021 | F8: Greenwich | G8: G | H8: 123 VALLEY DRIVE | I8: 2661200 | J8: 3000000 | K8: 0.887 | L8: 1.127311 | M8: Residential | N8: Undervalued
A9: 200661 | B9: 44438 | C9: August | D9: 2021 | E9: August,2021 | F9: New Canaan | G9: N | H9: 322 MAIN ST | I9: 1279460 | J9: 2400000 | K9: 0.5331 | L9: 1.8757913 | M9: Residential | N9: Undervalued
A10: 201437 | B10: 44397 | C10: July | D10: 2021 | E10: July,2021 | F10: Greenwich | G10: G | H10: 552 RIVER ROAD | I10: 1337630 | J10: 2300000 | K10: 0.5815 | L10: 1.719459 | M10: Residential | N10: Undervalued
A11: 200055 | B11: 44221 | C11: January | D11: 2021 | E11: January,2021 | F11: Washington | G11: W | H11: 136 OLD LITCHFIELD RD | I11: 1030330 | J11: 2285000 | K11: 0.4509 | L11: 2.2177361 | M11: Residential | N11: Overvalued
A12: 2016743 | B12: 44396 | C12: July | D12: 2021 | E12: July,2021 | F12: Redding | G12: R | H12: 241 ETHAN ALLEN HIGHWAY | I12: 1769800 | J12: 1800000 | K12: 0.9832 | L12: 1.0170641 | M12: Commercial | N12: Undervalued
A13: 200320 | B13: 44326 | C13: May | D13: 2021 | E13: May,2021 | F13: East Lyme | G13: E | H13: 9 FREEDOM WAY | I13: 776230 | J13: 1525000 | K13: 0.509 | L13: 1.9646239 | M13: Commercial | N13: Undervalued
... A303: 2000720 | B303: 44201 | C303: January | D303: 2021 | E303: January,2021 | F303: Stamford | G303: S | H303: 57 HARBOR DRIVE GARAGE G-105B | I303: 19110 | J303: 27500 | K303: 0.6949 | L303: 1.4390372 | M303: Residential | N303: Undervalued

Sheet month in 2021 highest sales
A1: Month Name | B1: Total Sales
A2: July | B2: 18232500
A3: April | B3: 9336250
A4: June | B4: 9113300 | E4: =TODAY() -> 46160
A5: September | B5: 9003365 | E5: =NOW() -> 46160.98
A6: March | B6: 8519700
A7: August | B7: 7569800
A8: January | B8: 7165711
A9: May | B9: 7091650
A10: February | B10: 5871800

Sheet dd
A1: Serial Number | B1: Date Recorded | C1: Month Name | D1: Year | E1: Month/Year | F1: Town | G1: Address | H1: Assessed Value | I1: Sale Amount | J1: Sales Ratio | K1: Sales Ratio 2 | L1: Property Type | M1: Value Status
A2: 160092 | B2: 42724 | C2: December | D2: 2016 | E2: December,2016 | F2: Rocky Hill | G2: 13D ROBBINS LANE | H2: 45150 | I2: 13650000 | J2: 0.003307692 | K2: 302.32558 | L2: Condo | M2: Overvalued
A3: 170261 | B3: 43221 | C3: May | D3: 2018 | E3: May,2018 | F3: New London | G3: 83 MANSFIELD RD 228 | H3: 30660 | I3: 3266250 | J3: 0.009386912 | K3: 106.53131 | L3: Condo | M3: Overvalued
A4: 170255 | B4: 43221 | C4: May | D4: 2018 | E4: May,2018 | F4: New London | G4: 83 MANSFIELD RD 220 | H4: 30660 | I4: 3266250 | J4: 0.009386912 | K4: 106.53131 | L4: Condo | M4: Overvalued
A5: 162063 | B5: 43005 | C5: September | D5: 2017 | E5: September,2017 | F5: Stamford | G5: 101 GROVE STREET G-17 | H5: 8190 | I5: 427500 | J5: 0.019157895 | K5: 52.197802 | L5: Condo | M5: Overvalued
A6: 161304 | B6: 42901 | C6: June | D6: 2017 | E6: June,2017 | F6: Stamford | G6: 12 DRYDEN STREET 1B | H6: 91980 | I6: 1323338 | J6: 0.069506052 | K6: 14.387236 | L6: Condo | M6: Overvalued
A7: 60890 | B7: 39190 | C7: April | D7: 2007 | E7: April,2007 | F7: Norwalk | G7: 33 NORTH WATER ST | H7: 44653 | I7: 429000 | J7: 0.10408625 | K7: 9.6074172 | L7: Condo | M7: Overvalued
A8: 90695 | B8: 40359 | C8: June | D8: 2010 | E8: June,2010 | F8: Norwalk | G8: 310 ELY AVE H | H8: 45757 | I8: 239900 | J8: 0.19073364 | K8: 5.2429137 | L8: Condo | M8: Overvalued
A9: 200195 | B9: 44312 | C9: April | D9: 2021 | E9: April,2021 | F9: Cromwell | G9: 34 SHUNPIKE ROAD | H9: 3360000 | I9: 5214750 | J9: 0.6443 | K9: 1.5520089 | L9: Commercial | M9: Undervalued
A10: 201233 | B10: 44369 | C10: June | D10: 2021 | E10: June,2021 | F10: Greenwich | G10: 11 BAYBERRY LANE | H10: 4259500 | I10: 4300000 | J10: 0.9905 | K10: 1.0095082 | L10: Residential | M10: Undervalued
A11: 201186 | B11: 44389 | C11: July | D11: 2021 | E11: July,2021 | F11: Danbury | G11: 28 MAIN ST | H11: 695500 | I11: 3200000 | J11: 0.21734375 | K11: 4.6010065 | L11: Commercial | M11: Overvalued
A12: 200645 | B12: 44244 | C12: February | D12: 2021 | E12: February,2021 | F12: Greenwich | G12: 123 VALLEY DRIVE | H12: 2661200 | I12: 3000000 | J12: 0.887 | K12: 1.127311 | L12: Residential | M12: Undervalued
A13: 200661 | B13: 44438 | C13: August | D13: 2021 | E13: August,2021 | F13: New Canaan | G13: 322 MAIN ST | H13: 1279460 | I13: 2400000 | J13: 0.5331 | K13: 1.8757913 | L13: Residential | M13: Undervalued
... A303: 2000720 | B303: 44201 | C303: January | D303: 2021 | E303: January,2021 | F303: Stamford | G303: 57 HARBOR DRIVE GARAGE G-105B | H303: 19110 | I303: 27500 | J303: 0.6949 | K303: 1.4390372 | L303: Residential | M303: Undervalued

Sheet Analysis
BC2: Top 5 Towns | CM2: EXPLORATORY DATA ANALYTICS
A3: Questions | BA3: Town | BB3: Sale Amount | BC3: Town | BD3: Sale Amount | BP3: 2. Which month in 2021 had the highest Sales | BY3: What is the Avg sales amount for each Property type | CH3: How many property sold below their Assessed level | CM3: A. Gen STATS | CU3: TEXT(CT4/1000000,"$0")&"M"
A4: 1. average and the median sales ratio | B4: AVG | C4: =AVERAGE(Table1_3__3[Sales Ratio 2]) -> 3.6700227 | E4: Town | F4: Sum of Sale Amount | G4: Average of Sales Ratio | H4: Count of Sale Amount2 | L4: Row Labels | M4: Sale Amount | N4: Count of Sale Amount | O4: Avg Sales Ratio | V4: Month | W4: Sum of Sale Amount | AU4: Row Labels | AV4: Sum of Amount | BA4: Rocky Hill | BB4: 0.10590135 | BC4: Rocky Hill | BD4: 0.10590135 | CM4: 1. what is the Avg and Median sales ratio | CS4: Total Sales | CT4: =SUM(Table1_3__3[Sale Amount]) -> 140431633 | CU4: =TEXT(CT4/1000000,"$0")&"M" -> $140M
B5: MEDIAN | C5: =MEDIAN(Table1_3__3[Sales Ratio 2]) -> 1.6633621 | E5: Ansonia | F5: 541000 | G5: 5.2926829e+08 | H5: 3 | L5: Ansonia | M5: 500000 | N5: 2 | O5: 0.62378571 | V5: January | W5: 7682911 | AI5: Serial Number | AJ5: Town | AK5: Address | AL5: Amount | AM5: Property Type | AU5: G | AV5: 4259500 | BA5: Stamford | BB5: 0.085836344 | BC5: Stamford | BD5: 0.085836344 | BP5: Year | BQ5: 2021 | CH5: COUNTIF | CI5: =COUNTIF(Table1_3__3[Sales Ratio 2],"<1") -> 0 | CM5: Avg. Sales Ratio | CN5: =AVERAGE('Main dataset'!L283:L303) -> 1.6633698 | CS5: Avg. Sales Ratio | CT5: =AVERAGE(Table1_3__3[Sales Ratio 2]) -> 3.6700227
E6: Ashford | F6: 430000 | G6: 0.5883 | H6: 1 | L6: Ashford | M6: 430000 | N6: 1 | O6: 0.5883 | V6: February | W6: 6840800 | AI6: 160092 | AJ6: {=VLOOKUP(Analysis!AI6,Table1_3__3[],{6,7,9,12},0)} -> Rocky Hill | AK6: R | AL6: 45150 | AM6: 302.32558 | AU6: C | AV6: 3360000 | BA6: Greenwich | BB6: 0.082282031 | BC6: Greenwich | BD6: 0.082282031 | BI6: 1. Which Town Has the most over valued properties based on the sales ratio | CM6: Median Sales Ratio | CN6: =MEDIAN(Table1_3__3[Sales Ratio 2]) -> 1.6633621 | CS6: Total No. Of Property Sold | CT6: =COUNT(Table1_3__3[Serial Number]) -> 302
E7: Avon | F7: 3767400 | G7: 0.673575 | H7: 4 | L7: Avon | M7: 3767400 | N7: 4 | O7: 0.673575 | V7: March | W7: 9929200 | AI7: 200195 | AJ7: {=VLOOKUP(Analysis!AI7,Table1_3__3[],{6,7,9,12},0)} -> Cromwell | AK7: C | AL7: 3360000 | AM7: 1.5520089 | AP7: Row Labels | AQ7: Sum of Sale Amount | AU7: N | AV7: 61320 | BA7: New London | BB7: 0.04787739 | BC7: New London | BD7: 0.04787739 | BP7: Row Labels | BQ7: Sum of Sale Amount | BZ7: Property Types | CA7: Average of Sale Amount | CS7: Avg.Assessed Value | CT7: =AVERAGE(Table1_3__3[Assessed Value]) -> 238484.4 | CU7: 238484
A8: 2. town with the highest sold property | B8: INDEX/MATCH/MAX | C8: =INDEX(Table1_3__3[Town],MATCH(MAX(Table1_3__3[Sale Amount]),Table1_3__3[Sale Amount],0)) -> Rocky Hill | E8: Berlin | F8: 1090991 | G8: 6005.2027 | H8: 3 | L8: Berlin | M8: 677500 | N8: 1 | O8: 0.6081 | V8: April | W8: 10525618 | AI8: 201233 | AJ8: {=VLOOKUP(Analysis!AI8,Table1_3__3[],{6,7,9,12},0)} -> Greenwich | AK8: G | AL8: 4259500 | AM8: 1.0095082 | AP8: 13D ROBBINS LANE | AQ8: 13650000 | AU8: R | AV8: 45150 | BA8: Cromwell | BB8: 0.042403196 | BC8: Cromwell | BD8: 0.042403196 | BP8: April,2021 | BQ8: 9336250 | BZ8: Apartments | CA8: 292833.33 | CS8: Town with Highest Sold Property | CT8: =INDEX(Table1_3__3[Town],MATCH(MAX(Table1_3__3[Sale Amount]),Table1_3__3[Sale Amount],0)) -> Rocky Hill
A9: Most Expentive Property type | B9: =INDEX(Table1_3__3[Property Type],MATCH(MAX(Table1_3__3[Sale Amount]),Table1_3__3[Sale Amount],0)) -> Condo | E9: Bethany | F9: 795000 | G9: 0.6427 | H9: 1 | L9: Bethany | M9: 795000 | N9: 1 | O9: 0.6427 | V9: May | W9: 16335860 | Z9: Monthly sales | AI9: 170261 | AJ9: {=VLOOKUP(Analysis!AI9,Table1_3__3[],{6,7,9,12},0)} -> New London | AK9: N | AL9: 30660 | AM9: 106.53131 | AP9: Rocky Hill | AQ9: 13650000 | BA9: Danbury | BB9: 0.041321174 | BP9: August,2021 | BQ9: 7569800 | BZ9: Commercial | CA9: 986120.04 | CM9: 2. Which town has the highest number of recorded propert sales | CS9: The Most Expensive Property type | CT9: =INDEX(Table1_3__3[Property Type],MATCH(MAX(Table1_3__3[Sale Amount]),Table1_3__3[Sale Amount],0)) -> Condo
A10: Total Sales amount | B10: =SUM(Table1_3__3[Sale Amount]) -> 140431633 | E10: Bethel | F10: 335000 | G10: 0.5115 | H10: 1 | L10: Bethel | M10: 335000 | N10: 1 | O10: 0.5115 | V10: June | W10: 13613338 | AI10: 170255 | AJ10: {=VLOOKUP(Analysis!AI10,Table1_3__3[],{6,7,9,12},0)} -> New London | AK10: N | AL10: 30660 | AM10: 106.53131 | AP10: 34 SHUNPIKE ROAD | AQ10: 5214750 | BA10: Avon | BB10: 0.026827289 | BP10: February,2021 | BQ10: 5871800 | BZ10: Condo | CA10: 386269.56 | CM10: =Analysis!AK21 -> 0
A11: Avg. Sales Ratio 2 | B11: =AVERAGE(Table1_3__3[Sales Ratio 2]) -> 3.6700227 | E11: Bethlehem | F11: 352000 | G11: 0.4798 | H11: 1 | L11: Bethlehem | M11: 352000 | N11: 1 | O11: 0.4798 | V11: July | W11: 19705766 | AP11: Cromwell | AQ11: 5214750 | BA11: New Canaan | BB11: 0.023142934 | BP11: January,2021 | BQ11: 7165711 | BZ11: Residential | CA11: 448088.67 | CM11: B. Sales by property type
A12: Total no. of property sold | B12: =COUNT(Table1_3__3[Serial Number]) -> 302 | E12: Bloomfield | F12: 383000 | G12: 0.79534474 | H12: 2 | L12: Bloomfield | M12: 383000 | N12: 2 | O12: 0.79534474 | V12: August | W12: 8461250 | AI12: TOP5 most expensive properties | AK12: DONE | AP12: 11 BAYBERRY LANE | AQ12: 4300000 | BA12: East Lyme | BB12: 0.020319496 | BP12: July,2021 | BQ12: 18232500 | CM12: 1. What is the avg. sales amount for Residential vs commercial property
A13: Avg. Assessed value | E13: Branford | F13: 2047250 | G13: 0.74001404 | H13: 6 | L13: Branford | M13: 2047250 | N13: 6 | O13: 0.74001404 | V13: September | W13: 12590314 | AP13: Greenwich | AQ13: 4300000 | BA13: Norwalk | BB13: 0.019150956 | BP13: June,2021 | BQ13: 9113300
E14: Bridgeport | F14: 560500 | G14: 211979.64 | H14: 6 | L14: Bridgeport | M14: 480500 | N14: 5 | O14: 0.5712943 | V14: October | W14: 8302200 | AI14: Serial Number | AJ14: Town | AK14: Address | AL14: Amount | AM14: Property Type | AP14: 83 MANSFIELD RD 228 | AQ14: 3266250 | BA14: Groton | BB14: 0.017891268 | BP14: March,2021 | BQ14: 8519700
E15: Bristol | F15: 1097900 | G15: 0.66420833 | H15: 6 | L15: Bristol | M15: 1097900 | N15: 6 | O15: 0.66420833 | V15: November | W15: 5424626 | AI15: 160092 | AJ15: {=VLOOKUP(Analysis!AI15,Table1_3__3[],{6,7,9,12},0)} -> Rocky Hill | AK15: R | AL15: 45150 | AM15: 302.32558 | AP15: New London | AQ15: 3266250 | BA15: Trumbull | BB15: 0.017880587 | BP15: May,2021 | BQ15: 7091650 | CO15: Property type | CP15: Average of Sale Amount
E16: Brookfield | F16: 330000 | G16: 0.60716875 | H16: 2 | L16: Brookfield | M16: 330000 | N16: 2 | O16: 0.60716875 | V16: December | W16: 21019750 | AI16: 200195 | AJ16: {=VLOOKUP(Analysis!AI16,Table1_3__3[],{6,7,9,12},0)} -> Cromwell | AK16: C | AL16: 3360000 | AM16: 1.5520089 | AP16: 83 MANSFIELD RD 220 | AQ16: 3266250 | BA16: Hartford | BB16: 0.017787303 | BP16: September,2021 | BQ16: 9003365 | CO16: Commercial | CP16: 986120.04
E17: Canaan | F17: 599000 | G17: 0.5939 | H17: 1 | L17: Canaan | M17: 599000 | N17: 1 | O17: 0.5939 | AI17: 201233 | AJ17: {=VLOOKUP(Analysis!AI17,Table1_3__3[],{6,7,9,12},0)} -> Greenwich | AK17: G | AL17: 4259500 | AM17: 1.0095082 | AP17: New London | AQ17: 3266250 | BA17: Washington | BB17: 0.016271263 | CO17: Residential | CP17: 448088.67
E18: Canton | F18: 497500 | G18: 0.57685517 | H18: 2 | L18: Canton | M18: 497500 | N18: 2 | O18: 0.57685517 | AI18: 170261 | AJ18: {=VLOOKUP(Analysis!AI18,Table1_3__3[],{6,7,9,12},0)} -> New London | AK18: N | AL18: 30660 | AM18: 106.53131 | BA18: Newtown | BB18: 0.015644623
E19: Cheshire | F19: 773900 | G19: 0.58798686 | H19: 3 | L19: Cheshire | M19: 773900 | N19: 3 | O19: 0.58798686 | AI19: 170255 | AJ19: {=VLOOKUP(Analysis!AI19,Table1_3__3[],{6,7,9,12},0)} -> New London | AK19: N | AL19: 30660 | AM19: 106.53131 | AY19: Town with the most sales percentage | BA19: New Haven | BB19: 0.015555612 | CA19: Row Labels | CB19: Count of Sale Amount
E20: Chester | F20: 418800 | G20: 0.5971 | H20: 1 | L20: Chester | M20: 418800 | N20: 1 | O20: 0.5971 | BA20: Shelton | BB20: 0.014982728 | CA20: Residential | CB20: 166 | CD20: =CA20 -> Residential | CE20: =CB20 -> 166
E21: Colchester | F21: 392000 | G21: 0.5711 | H21: 1 | L21: Colchester | M21: 392000 | N21: 1 | O21: 0.5711 | AI21: Bottom 5 based on sales Ratio | AY21: Town | AZ21: Average of Sale % | BA21: Enfield | BB21: 0.014661939 | CA21: Condo | CB21: 110 | CD21: =CA21 -> Condo | CE21: =CB21 -> 110
E22: Cornwall | F22: 385000 | G22: 0.6392 | H22: 1 | L22: Cornwall | M22: 385000 | N22: 1 | O22: 0.6392 | AI22: Serial Number | AJ22: Town | AK22: Address | AL22: Sales Ratio | AM22: Property Type | AY22: Cromwell | AZ22: 6.4028825 | BA22: Branford | BB22: 0.014578268 | CA22: Commercial | CB22: 23 | CD22: =CA22 -> Commercial | CE22: =CB22 -> 23
E23: Coventry | F23: 725000 | G23: 0.66615 | H23: 2 | L23: Coventry | M23: 725000 | N23: 2 | O23: 0.66615 | AI23: 100089 | AJ23: {=VLOOKUP(AI23,'Main dataset'!A2:$M$303,{6,7,10,12},0)} -> #N/A | AY23: Greenwich | AZ23: 4.9698347 | BA23: Norwich | BB23: 0.012863911 | BP23: Sum of Sale Amount | BQ23: Iinitial | CA23: Apartments | CB23: 3 | CD23: =CA23 -> Apartments | CE23: =CB23 -> 3
E24: Cromwell | F24: 5954750 | G24: 0.5996 | H24: 2 | L24: Cromwell | M24: 5954750 | N24: 2 | O24: 0.5996 | AI24: 160092 | AJ24: {=VLOOKUP(AI24,'Main dataset'!A3:$M$303,{6,7,10,12},0)} -> #N/A | AY24: Washington | AZ24: 4.9139214 | BA24: Redding | BB24: 0.012817625 | BQ24: W | BS24: W Total | CA24: Grand Total | CB24: 302
E25: Danbury | F25: 5802800 | G25: 0.61003244 | H25: 10 | L25: Danbury | M25: 5802800 | N25: 10 | O25: 0.61003244 | AI25: 170261 | AJ25: {=VLOOKUP(AI25,'Main dataset'!A4:$M$303,{6,7,10,12},0)} -> New London | AK25: N | AL25: 3266250 | AM25: 106.53131 | AY25: New London | AZ25: 4.8196572 | BA25: West Hartford | BB25: 0.011910493 | BP25: Row Labels | BQ25: Condo | BR25: Residential
E26: Darien | F26: 241368 | G26: 0.5495 | H26: 1 | L26: Darien | M26: 241368 | N26: 1 | O26: 0.5495 | AI26: 170255 | AJ26: {=VLOOKUP(AI26,'Main dataset'!A5:$M$303,{6,7,10,12},0)} -> New London | AK26: N | AL26: 3266250 | AM26: 106.53131 | AY26: Rocky Hill | AZ26: 3.9977761 | BA26: Stratford | BB26: 0.010937707 | BP26: W Hartford | BQ26: 244000 | BS26: 244000
E27: Derby | F27: 873000 | G27: 0.4023 | H27: 1 | L27: Derby | M27: 873000 | N27: 1 | O27: 0.4023 | AI27: 162063 | AJ27: {=VLOOKUP(AI27,'Main dataset'!A6:$M$303,{6,7,10,12},0)} -> Stamford | AK27: S | AL27: 427500 | AM27: 52.197802 | AY27: Redding | AZ27: 3.8709227 | BA27: New Britain | BB27: 0.010476984 | BP27: Wallingford | BQ27: 755500 | BS27: 755500
E28: East Granby | F28: 144900 | G28: 0.69634231 | H28: 1 | L28: East Granby | M28: 144900 | N28: 1 | O28: 0.69634231 | AY28: New Canaan | AZ28: 3.494583 | BA28: Meriden | BB28: 0.0099835056 | BP28: Washington | BR28: 2285000 | BS28: 2285000
E29: East Hampton | F29: 299000 | G29: 0.70434783 | H29: 1 | L29: East Hampton | M29: 299000 | N29: 1 | O29: 0.70434783 | AY29: Avon | AZ29: 2.0254603 | BA29: Farmington | BB29: 0.0094166818 | BP29: Waterbury | BQ29: 308850 | BR29: 411900 | BS29: 720750 | CM29: 2. Do commercial properties usually sell for more or less their assessed value
E30: East Hartford | F30: 50000 | G30: 0.77 | H30: 1 | L30: East Hartford | M30: 50000 | N30: 1 | O30: 0.77 | AY30: Derby | AZ30: 1.8773975 | BA30: Manchester | BB30: 0.0088477217 | BP30: Waterford | BR30: 710000 | BS30: 710000 | CM30: =AVERAGEIF('Avg. comm vs Residential sales'!M2:M189,"Commercial",'Avg. comm vs Residential sales'!L2:L189) -> 1.7091373 | CN30: Avg comm sales ratio
E31: East Haven | F31: 403000 | G31: 0.53200767 | H31: 3 | L31: East Haven | M31: 403000 | N31: 3 | O31: 0.53200767 | AY31: Bethany | AZ31: 1.7096575 | BA31: Westbrook | BB31: 0.0078828393 | BP31: Watertown | BR31: 223000 | BS31: 223000 | CM31: Interpretation: If Avg sales ratio >1 sell above
E32: East Lyme | F32: 2853500 | G32: 0.5174 | H32: 4 | L32: East Lyme | M32: 2853500 | N32: 4 | O32: 0.5174 | AY32: Newtown | AZ32: 1.5748921 | BA32: Bristol | BB32: 0.0078180391 | BP32: West Hartford | BQ32: 734710 | BR32: 937900 | BS32: 1672610 | CM32: if <1 sell below
E33: Enfield | F33: 2059000 | G33: 0.61108986 | H33: 8 | L33: Enfield | M33: 2059000 | N33: 8 | O33: 0.61108986 | AY33: East Lyme | AZ33: 1.5341219 | BA33: Southbury | BB33: 0.0075481569 | BP33: West Haven | BQ33: 578650 | BS33: 578650 | CM33: if =1 sell close to assessed value
E34: Essex | F34: 945000 | G34: 0.58225 | H34: 2 | L34: Essex | M34: 945000 | N34: 2 | O34: 0.58225 | AY34: Waterford | AZ34: 1.526864 | BA34: Plymouth | BB34: 0.007499101 | BP34: Westbrook | BR34: 1107000 | BS34: 1107000 | CM34: Result: Sells Above assessed value
E35: Fairfield | F35: 795000 | G35: 0.68680097 | H35: 2 | L35: Fairfield | M35: 795000 | N35: 2 | O35: 0.68680097 | AY35: Berlin | AZ35: 1.4569723 | BA35: Guilford | BB35: 0.0068360666 | BP35: Wethersfield | BQ35: 342700 | BR35: 572500 | BS35: 915200
E36: Farmington | F36: 2447400 | G36: 1798.4279 | H36: 6 | L36: Farmington | M36: 1322400 | N36: 5 | O36: 0.71351866 | AY36: Killingworth | AZ36: 1.3870806 | BA36: Essex | BB36: 0.0067292531 | BP36: Winchester | BQ36: 100000 | BS36: 100000 | CM36: C. Monthly/yearly Trends (2018 Above)
E37: Franklin | F37: 209000 | G37: 0.8936 | H37: 1 | L37: Franklin | M37: 209000 | N37: 1 | O37: 0.8936 | AY37: Groton | AZ37: 1.3507907 | BA37: Simsbury | BB37: 0.0066509232 | BP37: Windsor | BQ37: 238521 | BS37: 238521
E38: Glastonbury | F38: 681000 | G38: 0.69000745 | H38: 2 | L38: Glastonbury | M38: 681000 | N38: 2 | O38: 0.69000745 | AY38: Canaan | AZ38: 1.2881571 | BA38: Wethersfield | BB38: 0.0065170502 | BP38: Woodstock | BQ38: 281000 | BS38: 281000
E39: Greenwich | F39: 11555000 | G39: 0.67468 | H39: 5 | L39: Greenwich | M39: 11555000 | N39: 5 | O39: 0.67468 | AY39: Danbury | AZ39: 1.2478995 | BA39: Monroe | BB39: 0.0062663944 | BP39: Grand Total | BQ39: 3583931 | BR39: 6247300 | BS39: 9831231 | CN39: Row Labels | CO39: Sum of Sale Amount
A40: Row Labels | E40: Griswold | F40: 302000 | G40: 0.5729 | H40: 1 | L40: Griswold | M40: 302000 | N40: 1 | O40: 0.5729 | AY40: Roxbury | AZ40: 1.2365448 | BA40: Derby | BB40: 0.0062165481 | CN40: 2018 | CO40: 7174368
A41: Ansonia | E41: Groton | F41: 2512500 | G41: 0.52295699 | H41: 4 | L41: Groton | M41: 2512500 | N41: 4 | O41: 0.52295699 | AY41: Old Saybrook | AZ41: 1.2311685 | BA41: Vernon | BB41: 0.0062008821 | CN41: Jan | CO41: 59000
...

Sheet Dashboard

Sheet Sheet1
